2019-06-22 15:47:01,968 ERROR: Exception on /login [POST] [in /usr/local/lib/python3.7/site-packages/flask/app.py:1780]
Traceback (most recent call last):
  File "/usr/local/lib/python3.7/site-packages/flask/app.py", line 2311, in wsgi_app
    response = self.full_dispatch_request()
  File "/usr/local/lib/python3.7/site-packages/flask/app.py", line 1834, in full_dispatch_request
    rv = self.handle_user_exception(e)
  File "/usr/local/lib/python3.7/site-packages/flask/app.py", line 1737, in handle_user_exception
    reraise(exc_type, exc_value, tb)
  File "/usr/local/lib/python3.7/site-packages/flask/_compat.py", line 36, in reraise
    raise value
  File "/usr/local/lib/python3.7/site-packages/flask/app.py", line 1832, in full_dispatch_request
    rv = self.dispatch_request()
  File "/usr/local/lib/python3.7/site-packages/flask/app.py", line 1818, in dispatch_request
    return self.view_functions[rule.endpoint](**req.view_args)
  File "/Users/stevenjohn/Documents/Python/Flask/app/routes.py", line 16, in login
    if user is None or not user.check_pass(form.password.data):
  File "/Users/stevenjohn/Documents/Python/Flask/app/models.py", line 32, in check_pass
    return check_password_hash(self.password_hash, password)
  File "/usr/local/lib/python3.7/site-packages/werkzeug/security.py", line 218, in check_password_hash
    if pwhash.count("$") < 2:
AttributeError: 'NoneType' object has no attribute 'count'
2019-06-22 15:47:47,567 ERROR: Exception on /login [POST] [in /usr/local/lib/python3.7/site-packages/flask/app.py:1780]
Traceback (most recent call last):
  File "/usr/local/lib/python3.7/site-packages/flask/app.py", line 2311, in wsgi_app
    response = self.full_dispatch_request()
  File "/usr/local/lib/python3.7/site-packages/flask/app.py", line 1834, in full_dispatch_request
    rv = self.handle_user_exception(e)
  File "/usr/local/lib/python3.7/site-packages/flask/app.py", line 1737, in handle_user_exception
    reraise(exc_type, exc_value, tb)
  File "/usr/local/lib/python3.7/site-packages/flask/_compat.py", line 36, in reraise
    raise value
  File "/usr/local/lib/python3.7/site-packages/flask/app.py", line 1832, in full_dispatch_request
    rv = self.dispatch_request()
  File "/usr/local/lib/python3.7/site-packages/flask/app.py", line 1818, in dispatch_request
    return self.view_functions[rule.endpoint](**req.view_args)
  File "/Users/stevenjohn/Documents/Python/Flask/app/routes.py", line 16, in login
    if user is None or not user.check_pass(form.password.data):
  File "/Users/stevenjohn/Documents/Python/Flask/app/models.py", line 32, in check_pass
    return check_password_hash(self.password_hash, password)
  File "/usr/local/lib/python3.7/site-packages/werkzeug/security.py", line 218, in check_password_hash
    if pwhash.count("$") < 2:
AttributeError: 'NoneType' object has no attribute 'count'
2019-06-22 15:48:12,520 ERROR: Exception on /login [POST] [in /usr/local/lib/python3.7/site-packages/flask/app.py:1780]
Traceback (most recent call last):
  File "/usr/local/lib/python3.7/site-packages/flask/app.py", line 2311, in wsgi_app
    response = self.full_dispatch_request()
  File "/usr/local/lib/python3.7/site-packages/flask/app.py", line 1834, in full_dispatch_request
    rv = self.handle_user_exception(e)
  File "/usr/local/lib/python3.7/site-packages/flask/app.py", line 1737, in handle_user_exception
    reraise(exc_type, exc_value, tb)
  File "/usr/local/lib/python3.7/site-packages/flask/_compat.py", line 36, in reraise
    raise value
  File "/usr/local/lib/python3.7/site-packages/flask/app.py", line 1832, in full_dispatch_request
    rv = self.dispatch_request()
  File "/usr/local/lib/python3.7/site-packages/flask/app.py", line 1818, in dispatch_request
    return self.view_functions[rule.endpoint](**req.view_args)
  File "/Users/stevenjohn/Documents/Python/Flask/app/routes.py", line 16, in login
    if user is None or not user.check_pass(form.password.data):
  File "/Users/stevenjohn/Documents/Python/Flask/app/models.py", line 32, in check_pass
    return check_password_hash(self.password_hash, password)
  File "/usr/local/lib/python3.7/site-packages/werkzeug/security.py", line 218, in check_password_hash
    if pwhash.count("$") < 2:
AttributeError: 'NoneType' object has no attribute 'count'
2019-06-22 15:49:08,228 ERROR: Exception on /login [POST] [in /usr/local/lib/python3.7/site-packages/flask/app.py:1780]
Traceback (most recent call last):
  File "/usr/local/lib/python3.7/site-packages/flask/app.py", line 2311, in wsgi_app
    response = self.full_dispatch_request()
  File "/usr/local/lib/python3.7/site-packages/flask/app.py", line 1834, in full_dispatch_request
    rv = self.handle_user_exception(e)
  File "/usr/local/lib/python3.7/site-packages/flask/app.py", line 1737, in handle_user_exception
    reraise(exc_type, exc_value, tb)
  File "/usr/local/lib/python3.7/site-packages/flask/_compat.py", line 36, in reraise
    raise value
  File "/usr/local/lib/python3.7/site-packages/flask/app.py", line 1832, in full_dispatch_request
    rv = self.dispatch_request()
  File "/usr/local/lib/python3.7/site-packages/flask/app.py", line 1818, in dispatch_request
    return self.view_functions[rule.endpoint](**req.view_args)
  File "/Users/stevenjohn/Documents/Python/Flask/app/routes.py", line 16, in login
    if user is None or not user.check_pass(form.password.data):
  File "/Users/stevenjohn/Documents/Python/Flask/app/models.py", line 32, in check_pass
    return check_password_hash(self.password_hash, password)
  File "/usr/local/lib/python3.7/site-packages/werkzeug/security.py", line 218, in check_password_hash
    if pwhash.count("$") < 2:
AttributeError: 'NoneType' object has no attribute 'count'
2019-06-22 18:36:42,864 INFO: Microblog startup [in /Users/stevenjohn/Documents/Python/Flask/app/__init__.py:26]
2019-06-22 18:37:03,103 ERROR: Exception on /user/Johnny [GET] [in /usr/local/lib/python3.7/site-packages/flask/app.py:1780]
Traceback (most recent call last):
  File "/usr/local/lib/python3.7/site-packages/flask/app.py", line 2311, in wsgi_app
    response = self.full_dispatch_request()
  File "/usr/local/lib/python3.7/site-packages/flask/app.py", line 1834, in full_dispatch_request
    rv = self.handle_user_exception(e)
  File "/usr/local/lib/python3.7/site-packages/flask/app.py", line 1737, in handle_user_exception
    reraise(exc_type, exc_value, tb)
  File "/usr/local/lib/python3.7/site-packages/flask/_compat.py", line 36, in reraise
    raise value
  File "/usr/local/lib/python3.7/site-packages/flask/app.py", line 1832, in full_dispatch_request
    rv = self.dispatch_request()
  File "/usr/local/lib/python3.7/site-packages/flask/app.py", line 1818, in dispatch_request
    return self.view_functions[rule.endpoint](**req.view_args)
  File "/usr/local/lib/python3.7/site-packages/flask_login/utils.py", line 261, in decorated_view
    return func(*args, **kwargs)
  File "/Users/stevenjohn/Documents/Python/Flask/app/routes.py", line 73, in user
    pages = requests.args.get('page', 1, type=int)
NameError: name 'requests' is not defined
2019-06-22 18:38:11,928 INFO: Microblog startup [in /Users/stevenjohn/Documents/Python/Flask/app/__init__.py:26]
2019-06-22 18:38:43,364 ERROR: Exception on /explore [GET] [in /usr/local/lib/python3.7/site-packages/flask/app.py:1780]
Traceback (most recent call last):
  File "/usr/local/lib/python3.7/site-packages/flask/app.py", line 2311, in wsgi_app
    response = self.full_dispatch_request()
  File "/usr/local/lib/python3.7/site-packages/flask/app.py", line 1834, in full_dispatch_request
    rv = self.handle_user_exception(e)
  File "/usr/local/lib/python3.7/site-packages/flask/app.py", line 1737, in handle_user_exception
    reraise(exc_type, exc_value, tb)
  File "/usr/local/lib/python3.7/site-packages/flask/_compat.py", line 36, in reraise
    raise value
  File "/usr/local/lib/python3.7/site-packages/flask/app.py", line 1832, in full_dispatch_request
    rv = self.dispatch_request()
  File "/usr/local/lib/python3.7/site-packages/flask/app.py", line 1818, in dispatch_request
    return self.view_functions[rule.endpoint](**req.view_args)
  File "/usr/local/lib/python3.7/site-packages/flask_login/utils.py", line 261, in decorated_view
    return func(*args, **kwargs)
  File "/Users/stevenjohn/Documents/Python/Flask/app/routes.py", line 139, in explore
    page = request.args('page', 1, type=int)
TypeError: 'ImmutableMultiDict' object is not callable
2019-06-22 18:39:03,523 INFO: Microblog startup [in /Users/stevenjohn/Documents/Python/Flask/app/__init__.py:26]
2019-06-22 21:15:35,267 INFO: Microblog startup [in /Users/stevenjohn/Documents/Python/Flask/app/__init__.py:26]
2019-06-24 17:51:42,011 INFO: Microblog startup [in /Users/stevenjohn/Documents/Python/Flask/app/__init__.py:28]
2019-06-24 18:05:27,217 INFO: Microblog startup [in /Users/stevenjohn/Documents/Python/Flask/app/__init__.py:28]
2019-06-24 18:07:14,870 INFO: Microblog startup [in /Users/stevenjohn/Documents/Python/Flask/app/__init__.py:28]
2019-06-24 18:08:08,292 INFO: Microblog startup [in /Users/stevenjohn/Documents/Python/Flask/app/__init__.py:28]
2019-06-24 18:10:07,000 INFO: Microblog startup [in /Users/stevenjohn/Documents/Python/Flask/app/__init__.py:28]
2019-06-24 18:10:57,656 INFO: Microblog startup [in /Users/stevenjohn/Documents/Python/Flask/app/__init__.py:28]
2019-06-24 18:30:46,038 INFO: Microblog startup [in /Users/stevenjohn/Documents/Python/Flask/app/__init__.py:30]
2019-06-24 18:36:20,334 INFO: Microblog startup [in /Users/stevenjohn/Documents/Python/Flask/app/__init__.py:30]
